Workbook

Sheet Dashboard
A1: DASHBOARD LAMARAN & FREELANCE | E1: =TODAY() -> 46284
A2: Semua angka formula otomatis dari sheet Full-Time & Freelance. Target diisi manual (sel kuning).
B4: TARGET (isi manual di sel kuning)
B5: Metrik | C5: Target | D5: Aktual | E5: Progress
B6: Perusahaan dilamar | C6: 5 | D6: =COUNTA('Full-Time'!$C$5:$C$124)-COUNTIF('Full-Time'!$K$5:$K$124,"Wishlist") -> 5 | E6: =IF($C6=0,"",$D6/$C6) -> 1 | F6: Total lamaran terkirim
B7: Masuk tahap interview | C7: 3 | D7: =SUMPRODUCT(--('Full-Time'!$K$5:$K$124<>""),--('Full-Time'!$K$5:$K$124<>"Wishlist"),--('Full-Time'!$K$5:$K$124<>"Apply"),--('Full-Time'!$K$5:$K$124<>"Screening HR"),--('Full-Time'!$K$5:$K$124<>"Ditolak"),--('Full-Time'!$K$5:$K$124<>"Ghosting"))+COUNTIF('Full-Time'!$K$5:$K$124,"Ditolak")*0 -> 0 | E7: =IF($C7=0,"",$D7/$C7) -> 0 | F7: Interview HR ke atas (status saat ini)
B8: Lolos ke interview ke-2 | C8: 2 | D8: =COUNTIF('Full-Time'!$K$5:$K$124,"Interview User")+COUNTIF('Full-Time'!$K$5:$K$124,"Interview Final")+COUNTIF('Full-Time'!$K$5:$K$124,"Technical Test")+COUNTIF('Full-Time'!$K$5:$K$124,"Offer")+COUNTIF('Full-Time'!$K$5:$K$124,"Diterima") -> 0 | E8: =IF($C8=0,"",$D8/$C8) -> 0 | F8: Interview User / Final / Test / Offer
B9: Offer diterima | C9: 1 | D9: =COUNTIF('Full-Time'!$K$5:$K$124,"Offer")+COUNTIF('Full-Time'!$K$5:$K$124,"Diterima") -> 0 | E9: =IF($C9=0,"",$D9/$C9) -> 0 | F9: Target minimal 1
B10: Freelance closing (Deal ke atas) | C10: 1 | D10: =COUNTIF(Freelance!$I$5:$I$84,"Deal / DP")+COUNTIF(Freelance!$I$5:$I$84,"Dikerjakan")+COUNTIF(Freelance!$I$5:$I$84,"Review Klien")+COUNTIF(Freelance!$I$5:$I$84,"Selesai") -> 0 | E10: =IF($C10=0,"",$D10/$C10) -> 0 | F10: Target minimal 1 project masuk
B12: FUNNEL FULL-TIME
B13: Wishlist | C13: =COUNTIF('Full-Time'!$K$5:$K$124,"Wishlist") -> 0
B14: Apply | C14: =COUNTIF('Full-Time'!$K$5:$K$124,"Apply") -> 5
B15: Screening HR | C15: =COUNTIF('Full-Time'!$K$5:$K$124,"Screening HR") -> 0
B16: Interview HR | C16: =COUNTIF('Full-Time'!$K$5:$K$124,"Interview HR") -> 0
B17: Interview User | C17: =COUNTIF('Full-Time'!$K$5:$K$124,"Interview User") -> 0
B18: Interview Final | C18: =COUNTIF('Full-Time'!$K$5:$K$124,"Interview Final") -> 0
B19: Technical Test | C19: =COUNTIF('Full-Time'!$K$5:$K$124,"Technical Test") -> 0
B20: Offer | C20: =COUNTIF('Full-Time'!$K$5:$K$124,"Offer") -> 0
B21: Diterima | C21: =COUNTIF('Full-Time'!$K$5:$K$124,"Diterima") -> 0
B22: Ditolak | C22: =COUNTIF('Full-Time'!$K$5:$K$124,"Ditolak") -> 0
B23: Ghosting | C23: =COUNTIF('Full-Time'!$K$5:$K$124,"Ghosting") -> 0
B24: Response rate (dibalas / dilamar) | C24: =IFERROR((COUNTA('Full-Time'!$C$5:$C$124)-COUNTIF('Full-Time'!$K$5:$K$124,"Wishlist")-COUNTIF('Full-Time'!$K$5:$K$124,"Apply")-COUNTIF('Full-Time'!$K$5:$K$124,"Ghosting"))/(COUNTA('Full-Time'!$C$5:$C$124)-COUNTIF('Full-Time'!$K$5:$K$124,"Wishlist")),"") -> 0 | F24: Yang lanjut proses dibagi total lamaran
B25: Lamaran nganggur >14 hari | C25: =SUMPRODUCT(--('Full-Time'!$N$5:$N$124<>""),--('Full-Time'!$N$5:$N$124>14),(('Full-Time'!$K$5:$K$124="Apply")+('Full-Time'!$K$5:$K$124="Screening HR"))) -> 0 | F25: Waktunya follow up
B27: PIPELINE FREELANCE
B28: Lead | C28: =COUNTIF(Freelance!$I$5:$I$84,"Lead") -> 0
B29: Proposal Terkirim | C29: =COUNTIF(Freelance!$I$5:$I$84,"Proposal Terkirim") -> 1
B30: Negosiasi | C30: =COUNTIF(Freelance!$I$5:$I$84,"Negosiasi") -> 0
B31: Deal / DP | C31: =COUNTIF(Freelance!$I$5:$I$84,"Deal / DP") -> 0
B32: Dikerjakan | C32: =COUNTIF(Freelance!$I$5:$I$84,"Dikerjakan") -> 0
B33: Selesai | C33: =COUNTIF(Freelance!$I$5:$I$84,"Selesai") -> 0
B34: Batal | C34: =COUNTIF(Freelance!$I$5:$I$84,"Batal") -> 0
B35: Total nilai pipeline (Rp) | C35: =SUM(Freelance!$H$5:$H$84) -> 12000000 | F35: Semua project apapun statusnya
B36: Nilai tertimbang / weighted (Rp) | C36: =SUM(Freelance!$K$5:$K$84) -> 6000000 | F36: Nilai x probabilitas
B37: Nilai sudah closing (Rp) | C37: =SUMIF(Freelance!$I$5:$I$84,"Deal / DP",Freelance!$H$5:$H$84)+SUMIF(Freelance!$I$5:$I$84,"Dikerjakan",Freelance!$H$5:$H$84)+SUMIF(Freelance!$I$5:$I$84,"Review Klien",Freelance!$H$5:$H$84)+SUMIF(Freelance!$I$5:$I$84,"Selesai",Freelance!$H$5:$H$84) -> 0 | F37: Yang udah deal
B38: Uang sudah masuk (Rp) | C38: =SUM(Freelance!$P$5:$P$84) -> 0 | F38: Pembayaran diterima
B39: Sisa tagihan (Rp) | C39: =SUM(Freelance!$Q$5:$Q$84) -> 12000000 | F39: Belum dibayar klien
B40: Win rate freelance | C40: =IFERROR((COUNTIF(Freelance!$I$5:$I$84,"Deal / DP")+COUNTIF(Freelance!$I$5:$I$84,"Dikerjakan")+COUNTIF(Freelance!$I$5:$I$84,"Review Klien")+COUNTIF(Freelance!$I$5:$I$84,"Selesai"))/(COUNTA(Freelance!$C$5:$C$84)-COUNTIF(Freelance!$I$5:$I$84,"Lead")),"") -> 0 | F40: Closing dibagi proposal yang keluar
B42: CARA PAKAI
B43: 1. Tiap lamaran baru -> tambah 1 baris di sheet Full-Time, isi minimal Tgl Apply, Perusahaan, Posisi, Status.
B44: 2. Kolom Status pakai dropdown. Update status tiap ada kabar, jangan lupa isi Tgl Update Terakhir.
...

Sheet Lists
A1: Status Fulltime | B1: Sumber | C1: Tipe Kerja | D1: Prioritas | E1: Status Freelance | F1: Sumber Freelance | G1: Status Bayar | H1: Stack
A2: Wishlist | B2: LinkedIn | C2: WFO | D2: Tinggi | E2: Lead | F2: Referral | G2: Belum Ditagih | H2: Laravel
A3: Apply | B3: JobStreet | C3: WFH / Remote | D3: Sedang | E3: Proposal Terkirim | F3: Upwork | G3: Invoice Terkirim | H3: Golang
A4: Screening HR | B4: Glints | C4: Hybrid | D4: Rendah | E4: Negosiasi | F4: Fiverr | G4: DP Masuk | H4: Next.js
A5: Interview HR | B5: Kalibrr | E5: Deal / DP | F5: Sribulancer | G5: Lunas | H5: React
A6: Interview User | B6: Dealls | E6: Dikerjakan | F6: Projects.co.id | G6: Telat Bayar | H6: Fullstack
A7: Interview Final | B7: Website Perusahaan | E7: Review Klien | F7: LinkedIn | G7: Macet | H7: API / Backend
A8: Technical Test | B8: Referral | E8: Selesai | F8: Komunitas / Discord | H8: Landing Page
A9: Offer | B9: Recruiter DM | E9: Batal | F9: Teman / Eks Kantor | H9: Maintenance
A10: Diterima | B10: Job Fair | E10: Ghosting | F10: Lainnya | H10: Lainnya
A11: Ditolak | B11: Lainnya
A12: Ghosting
A13: Withdraw

Sheet Full-Time
A1: TRACKER LAMARAN FULL-TIME
A2: Isi kolom putih. Kolom abu-abu (Umur) formula otomatis. Baris 5 = contoh, hapus/timpa aja.
A4: No | B4: Tgl Apply | C4: Perusahaan | D4: Posisi | E4: Lokasi | F4: Tipe Kerja | G4: Sumber | H4: Link Lowongan | I4: Ekspektasi Gaji (Rp) | J4: Prioritas | K4: Status | L4: Tahap Ke- | M4: Tgl Update Terakhir | N4: Umur (hari) | O4: Next Action | P4: Tgl Follow-up | Q4: Kontak (nama / email) | R4: Catatan
A5: 1 | B5: 46284 | C5: PT Primagraha Keramindo | D5: PHP Developer | E5: Jakarta Barat, Jakarta Raya | F5: WFO | G5: JobStreet | H5: https://id.jobstreet.com/id/job/94521495?ref=applied | I5: 8000000 | J5: Rendah | K5: Apply | L5: =IFERROR(IF($K5="","",MATCH($K5,Lists!$A$2:$A$13,0)-1),"") -> 1 | M5: 46284 | N5: =IF($B5="","",TODAY()-$B5) -> 0
A6: =IF($C6="","",COUNTA($C$5:$C6)) -> 2 | B6: 46284 | C6: Karyamas Plantation | D6: IT Web Developer | E6: Jakarta Pusat, Jakarta Raya | F6: WFO | G6: JobStreet | H6: https://id.jobstreet.com/id/job/94632028?ref=applied | I6: 8000000 | J6: Rendah | K6: Apply | L6: =IFERROR(IF($K6="","",MATCH($K6,Lists!$A$2:$A$13,0)-1),"") -> 1 | M6: 46284 | N6: =IF($B6="","",TODAY()-$B6) -> 0
A7: =IF($C7="","",COUNTA($C$5:$C7)) -> 3 | B7: 46284 | C7: Jual Emas Indonesia | D7: Full Stack Web Developer | E7: Jakarta Selatan, Jakarta Raya | F7: WFO | G7: JobStreet | H7: https://id.jobstreet.com/id/my-activity/applied-jobs/94625401 | I7: 8000000 | J7: Rendah | K7: Apply | L7: =IFERROR(IF($K7="","",MATCH($K7,Lists!$A$2:$A$13,0)-1),"") -> 1 | M7: 46284 | N7: =IF($B7="","",TODAY()-$B7) -> 0
A8: =IF($C8="","",COUNTA($C$5:$C8)) -> 4 | B8: 46284 | C8: PT DWIDA AGRO TAMA | D8: IT Staff - Full Stack | E8: Jakarta Raya | F8: WFO | G8: JobStreet | H8: https://id.jobstreet.com/id/my-activity/applied-jobs/94496636 | I8: 8000000 | J8: Rendah | K8: Apply | L8: =IFERROR(IF($K8="","",MATCH($K8,Lists!$A$2:$A$13,0)-1),"") -> 1 | M8: 46284 | N8: =IF($B8="","",TODAY()-$B8) -> 0
A9: =IF($C9="","",COUNTA($C$5:$C9)) -> 5 | B9: 46284 | C9: PT China Taiping Insurance Indonesia | D9: IT DEVELOPER | E9: Jakarta Selatan, Jakarta Raya | F9: WFO | G9: JobStreet | H9: https://id.jobstreet.com/id/job/94552212?ref=applied | I9: 8000000 | J9: Rendah | K9: Apply | L9: =IFERROR(IF($K9="","",MATCH($K9,Lists!$A$2:$A$13,0)-1),"") -> 1 | M9: 46284 | N9: =IF($B9="","",TODAY()-$B9) -> 0
A10: =IF($C10="","",COUNTA($C$5:$C10)) | L10: =IFERROR(IF($K10="","",MATCH($K10,Lists!$A$2:$A$13,0)-1),"") | N10: =IF($B10="","",TODAY()-$B10)
A11: =IF($C11="","",COUNTA($C$5:$C11)) | L11: =IFERROR(IF($K11="","",MATCH($K11,Lists!$A$2:$A$13,0)-1),"") | N11: =IF($B11="","",TODAY()-$B11)
A12: =IF($C12="","",COUNTA($C$5:$C12)) | L12: =IFERROR(IF($K12="","",MATCH($K12,Lists!$A$2:$A$13,0)-1),"") | N12: =IF($B12="","",TODAY()-$B12)
A13: =IF($C13="","",COUNTA($C$5:$C13)) | L13: =IFERROR(IF($K13="","",MATCH($K13,Lists!$A$2:$A$13,0)-1),"") | N13: =IF($B13="","",TODAY()-$B13)
A14: =IF($C14="","",COUNTA($C$5:$C14)) | L14: =IFERROR(IF($K14="","",MATCH($K14,Lists!$A$2:$A$13,0)-1),"") | N14: =IF($B14="","",TODAY()-$B14)
A15: =IF($C15="","",COUNTA($C$5:$C15)) | L15: =IFERROR(IF($K15="","",MATCH($K15,Lists!$A$2:$A$13,0)-1),"") | N15: =IF($B15="","",TODAY()-$B15)
A16: =IF($C16="","",COUNTA($C$5:$C16)) | L16: =IFERROR(IF($K16="","",MATCH($K16,Lists!$A$2:$A$13,0)-1),"") | N16: =IF($B16="","",TODAY()-$B16)
A17: =IF($C17="","",COUNTA($C$5:$C17)) | L17: =IFERROR(IF($K17="","",MATCH($K17,Lists!$A$2:$A$13,0)-1),"") | N17: =IF($B17="","",TODAY()-$B17)
A18: =IF($C18="","",COUNTA($C$5:$C18)) | L18: =IFERROR(IF($K18="","",MATCH($K18,Lists!$A$2:$A$13,0)-1),"") | N18: =IF($B18="","",TODAY()-$B18)
A19: =IF($C19="","",COUNTA($C$5:$C19)) | L19: =IFERROR(IF($K19="","",MATCH($K19,Lists!$A$2:$A$13,0)-1),"") | N19: =IF($B19="","",TODAY()-$B19)
A20: =IF($C20="","",COUNTA($C$5:$C20)) | L20: =IFERROR(IF($K20="","",MATCH($K20,Lists!$A$2:$A$13,0)-1),"") | N20: =IF($B20="","",TODAY()-$B20)
A21: =IF($C21="","",COUNTA($C$5:$C21)) | L21: =IFERROR(IF($K21="","",MATCH($K21,Lists!$A$2:$A$13,0)-1),"") | N21: =IF($B21="","",TODAY()-$B21)
... A124: =IF($C124="","",COUNTA($C$5:$C124)) | L124: =IFERROR(IF($K124="","",MATCH($K124,Lists!$A$2:$A$13,0)-1),"") | N124: =IF($B124="","",TODAY()-$B124)

Sheet Freelance
A1: TRACKER PROJECT FREELANCE
A2: Isi kolom putih. Kolom abu-abu (Nilai Tertimbang, Sisa Tagihan) formula otomatis. Baris 5 = contoh.
A4: No | B4: Tgl Masuk Lead | C4: Klien | D4: Nama Project | E4: Stack | F4: Sumber | G4: Scope Singkat | H4: Nilai Penawaran (Rp) | I4: Status | J4: Probabilitas | K4: Nilai Tertimbang (Rp) | L4: Deadline Proposal | M4: Tgl Mulai | N4: Deadline Project | O4: Status Bayar | P4: Sudah Dibayar (Rp) | Q4: Sisa Tagihan (Rp) | R4: Next Action | S4: Catatan
A5: 1 | B5: 2026-09-10 | C5: Toko Berkah Jaya | D5: Company profile + katalog produk | E5: Next.js | F5: Referral | G5: Landing page 5 halaman + CMS sederhana | H5: 12000000 | I5: Proposal Terkirim | J5: 0.5 | K5: =IF($H5="","",$H5*IF($J5="",0,$J5)) -> 6000000 | L5: 2026-09-25 | N5: 2026-10-20 | O5: Belum Ditagih | P5: 0 | Q5: =IF($H5="","",$H5-IF($P5="",0,$P5)) -> 12000000 | R5: Follow up proposal H+3 | S5: Budget klien masih nego di 10jt
A6: =IF($C6="","",COUNTA($C$5:$C6)) | K6: =IF($H6="","",$H6*IF($J6="",0,$J6)) | Q6: =IF($H6="","",$H6-IF($P6="",0,$P6))
A7: =IF($C7="","",COUNTA($C$5:$C7)) | K7: =IF($H7="","",$H7*IF($J7="",0,$J7)) | Q7: =IF($H7="","",$H7-IF($P7="",0,$P7))
A8: =IF($C8="","",COUNTA($C$5:$C8)) | K8: =IF($H8="","",$H8*IF($J8="",0,$J8)) | Q8: =IF($H8="","",$H8-IF($P8="",0,$P8))
A9: =IF($C9="","",COUNTA($C$5:$C9)) | K9: =IF($H9="","",$H9*IF($J9="",0,$J9)) | Q9: =IF($H9="","",$H9-IF($P9="",0,$P9))
A10: =IF($C10="","",COUNTA($C$5:$C10)) | K10: =IF($H10="","",$H10*IF($J10="",0,$J10)) | Q10: =IF($H10="","",$H10-IF($P10="",0,$P10))
A11: =IF($C11="","",COUNTA($C$5:$C11)) | K11: =IF($H11="","",$H11*IF($J11="",0,$J11)) | Q11: =IF($H11="","",$H11-IF($P11="",0,$P11))
A12: =IF($C12="","",COUNTA($C$5:$C12)) | K12: =IF($H12="","",$H12*IF($J12="",0,$J12)) | Q12: =IF($H12="","",$H12-IF($P12="",0,$P12))
A13: =IF($C13="","",COUNTA($C$5:$C13)) | K13: =IF($H13="","",$H13*IF($J13="",0,$J13)) | Q13: =IF($H13="","",$H13-IF($P13="",0,$P13))
A14: =IF($C14="","",COUNTA($C$5:$C14)) | K14: =IF($H14="","",$H14*IF($J14="",0,$J14)) | Q14: =IF($H14="","",$H14-IF($P14="",0,$P14))
A15: =IF($C15="","",COUNTA($C$5:$C15)) | K15: =IF($H15="","",$H15*IF($J15="",0,$J15)) | Q15: =IF($H15="","",$H15-IF($P15="",0,$P15))
A16: =IF($C16="","",COUNTA($C$5:$C16)) | K16: =IF($H16="","",$H16*IF($J16="",0,$J16)) | Q16: =IF($H16="","",$H16-IF($P16="",0,$P16))
A17: =IF($C17="","",COUNTA($C$5:$C17)) | K17: =IF($H17="","",$H17*IF($J17="",0,$J17)) | Q17: =IF($H17="","",$H17-IF($P17="",0,$P17))
... A84: =IF($C84="","",COUNTA($C$5:$C84)) | K84: =IF($H84="","",$H84*IF($J84="",0,$J84)) | Q84: =IF($H84="","",$H84-IF($P84="",0,$P84))
G86: TOTAL | H86: =SUM(H5:H84) -> 12000000 | K86: =SUM(K5:K84) -> 6000000 | P86: =SUM(P5:P84) -> 0 | Q86: =SUM(Q5:Q84) -> 12000000
